Workbook

Sheet Upriver
A3: CLIENTE :
A5: BUQUE :
A8: UP RIVER
A9: Puerto
A10: Terminal
A11: CF | B11: 187
A12: TRN | B12: 27149 | C12: 47.45
A13: Carga
A16: PORT DUES
A17: TRN | B17: DIAS
A18: =B12 -> 27149 | B18: 2
A19: =A18*0.37*B18 -> 20090.26
A22: TRN | B22: Entrance And Light Dues | N22: NOTAS DE CREDITO
A23: =B12 -> 27149 | B23: =A23*0.059*1.2 -> 1922.1492
A26: RIVER PLATE | G26: RIPLA | O26: ENTRADA | P26: SALIDA
B27: ENTRADA | C27: SALIDA | E27: ENTRADA | F27: SALIDA | N27: RIPLA | O27: 0.12 | Q27: 0.04 | R27: =(E32+4440)*4% -> 937.44
A28: Pilotos | B28: 2 | C28: 2 | E28: =(+Calculos!A10+Calculos!A12)*Calculos!B5 -> 7480 | F28: =(Calculos!H10+Calculos!H12)*Calculos!I5 -> 9724 | O28: =+E32*O27 -> 2279.52 | P28: =+F32*O27 -> 3078.96 | Q28: 0.04 | R28: =(F32+4440)*4% -> 1203.92
A29: Calado | B29: 0 | C29: 10.41 | E29: =SUM(Calculos!A13:A17)*Calculos!B5 -> 11516 | F29: =SUM(Calculos!H13:H17)*Calculos!I5 -> 11516 | N29: SI ES CANAL ROJO 17%
A30: Demora hs | B30: 0 | C30: 6 | E30: =Calculos!A18 -> 0 | F30: =Calculos!H18 -> 1800
A31: Fondeos | B31: 0 | C31: 1 | E31: =Calculos!A19 -> 0 | F31: =Calculos!H19 -> 2618
E32: =SUM(E28:E31) -> 18996 | F32: =SUM(F28:F31) -> 25658
E33: =IF(G26="INDEPENDIENTE",E28+15900,IF(G26="RIPLA",E28+15960,0)) -> 23440 | F33: =IF(G26="INDEPENDIENTE",F28+15900,IF(G26="RIPLA",F28+15960,0)) -> 25684
A36: RIVER PARANA | N36: ENTRADA | O36: MOV | P36: MOV | Q36: SALIDA
B37: ENTRADA | C37: MOV | D37: MOV | E37: SALIDA | G37: ENTRADA | H37: MOV | I37: MOV | J37: SALIDA | N37: 0.1
A38: Pilotos | B38: 2 | C38: 0 | D38: 0 | E38: 2 | G38: =Calculos!A34+Calculos!A35+Calculos!A36 -> 12376 | H38: =Calculos!D34+Calculos!D35+Calculos!D36 -> 0 | I38: =Calculos!G34+Calculos!G35+Calculos!G36 -> 0 | J38: =Calculos!J34+Calculos!J35+Calculos!J36 -> 15652 | N38: =+G43*N37 -> 2495.4 | O38: =+H43*N37 -> 0 | P38: =+I43*N37 -> 0 | Q38: =+J43*N37 -> 2898
A39: Distancia | B39: 391 | C39: 0 | D39: 0 | E39: 377 | G39: 9960 | H39: =Calculos!D39+Calculos!D40 -> 0 | I39: =Calculos!G39+Calculos!G40 -> 0 | J39: =Calculos!J39+Calculos!J40 -> 9960 | N39: SI ES CANAL ROJO 15% (VER) / COFCO ARMADOR multipar/ river 13% cofco
A40: Calado | B40: 0 | C40: 0 | D40: 0 | E40: 10.41 | G40: =Calculos!A37 -> 0 | H40: =Calculos!D37 -> 0 | I40: =Calculos!G37 -> 0 | J40: =Calculos!J37 -> 750 | N40: SI EL BUQUE ES COFCO NCI: | P40: 0.04
A41: Demora hs | B41: 0 | C41: 0 | D41: 0 | E41: 2.5 | G41: =Calculos!A38 -> 2618 | H41: =Calculos!D38 -> 0 | I41: =Calculos!G38 -> 0 | J41: =Calculos!J38 -> 2618 | N41: =+G43*P40 -> 998.16 | O41: =+H43*P40 -> 0 | P41: =+I43*P40 -> 0 | Q41: =+J43*P40 -> 1159.2
A42: Fondeos | B42: 1 | C42: 0 | D42: 0 | E42: 1
G43: =SUM(G38:G41) -> 24954 | H43: =SUM(H38:H41) -> 0 | I43: =SUM(I38:I41) -> 0 | J43: =SUM(J38:J41) -> 28980
G44: =+G43+H43+J43+I43 -> 53934
A47: PORT PILOTS | N47: 0.09
B48: ENTRADA | C48: SHIFT | D48: SHIFT | E48: SALIDA | G48: SERV | H48: =IF(B38>0,Calculos!E55,0) -> 2618 | I48: =IF(C38>0,Calculos!F55,0) -> 0 | J48: =IF(D38>0,Calculos!G55,0) -> 0 | K48: =IF(E38>0,Calculos!H55,0) -> 3403.4 | N48: Entrada | O48: =H53*N47 -> 732.24
A49: Demora hs | B49: 0 | C49: 0 | D49: 0 | E49: 0 | G49: DEMORA | H49: =Calculos!E56 -> 0 | I49: =Calculos!F56 -> 0 | J49: =Calculos!G56 -> 0 | K49: =Calculos!H56 -> 0 | N49: Shift | O49: =I53*N47 -> 0
A50: REC/EXTRA | B50: 1 | C50: 0 | D50: 0 | E50: 0 | G50: RECC EXTRA | H50: =Calculos!E57 -> 2618 | I50: =Calculos!F57 -> 0 | J50: =Calculos!G57 -> 0 | K50: =Calculos!H57 -> 0 | N50: Shift | O50: =J53*N47 -> 0
G51: CONEXO | H51: =Calculos!E58 -> 2900 | I51: =Calculos!F58 -> 0 | J51: =Calculos!G58 -> 0 | K51: =Calculos!H58 -> 2900 | N51: Salida | O51: =K53*N47 -> 567.306
G52: PILOTAJE
G53: TOTAL | H53: =SUM(H48:H51) -> 8136 | I53: =SUM(I48:I51) -> 0 | J53: =SUM(J48:J51) -> 0 | K53: =SUM(K48:K52) -> 6303.4
H54: =+H53+I53+K53+J53 -> 14439.4

Sheet Ajustada
D10: From 23-02-26 to 24-02-26
C11: Initial | D11: Close to Real
B12: VESSEL | C12: PISTI | D12: PISTI
B13: PORT | C13: GRAL LAGOS | D13: GRAL LAGOS
B14: BERTH | C14: ARROYO SECO - ADM | D14: ARROYO SECO - ADM
B15: PERMANENCY | C15: 2 days | D15: 2 days
B16: CURRENCY | C16: USD | D16: USD
B17: ITEM | C17: AMOUNT | D17: AMOUNT
B18: Port dues | C18: 14201 | D18: =Upriver!A19 -> 20090.26 | F18: Comentarios:
B19: Entrance and light dues | C19: 1359 | D19: 1902 | F19: Inicial base a otras medidas
B20: Toll dues | C20: 90432 | D20: 115544 | F20: Plate sale con Virado de anclas y 6hs de demora
B21: River plate pilotage | C21: 39328 | D21: =(7480+9724+15956*2)*0.84 -> 41257.44 | F21: Paraná entra con Fondeo
B22: River plate pilotage (delay) | D22: =1800*0.84 -> 1512 | F22: Paraná sale con Fondeo en ZC por fuertes vientos y 2,5hs de demora
B23: River plate pilotage anchorage maneuver | D23: =2618*0.84 -> 2199.12 | F23: Port entra con Zarpada de rada
B24: River parana pilotage | C24: 39865 | D24: =(12376+15652+9960*2)*0.88 -> 42194.24 | F24: Completa en Bahia Blanca
B25: River parana pilotage (delay) | D25: =750*0.88 -> 660
B26: River parana pilotage anchorage maneuver | D26: =5236*0.88 -> 4607.68
B27: Port pilotage | C27: 9190 | D27: =(5236+3403.4+2900*2)*0.91 -> 13139.854
B28: Launch services for clearence at roads | C28: 575 | D28: 1150
B29: Mooring & unmooring services | C29: 3300 | D29: 3300
B30: Custom house expenses | C30: 200 | D30: 530
B31: Custom house Permanence | D31: 200
B32: Migration expenses | C32: 1875 | D32: 1875
B33: Sanitary dues and free practique | C33: 597 | D33: 486
B34: Garbage compulsory inspection | C34: 96 | D34: 93
B35: Mandatory holds inspection at roads | C35: 1350 | D35: 1812
B36: Headclerk compulsory services | C36: 2992 | D36: =2355*0.9 -> 2119.5
B37: Launch services for draft survey (3) | D37: 1725
B38: Draft survey | D38: 1340
B39: Full on hire BQS | D39: 960
B40: Pest control | D40: 650
B41: Launch services for holds re-inspection (Owner expenses) | D41: 1150
B42: Mandatory holds re-inspection at roads (Owner expenses) | D42: 1010
B43: Holds cleaning expenses (Owner expenses) | D43: 600
B44: Wash water expenses (Owner expenses) | D44: 200
B45: Agency fee | C45: 2000 | D45: 2000
B47: TOTAL | C47: =SUM(C18:C45) -> 207360 | D47: =SUM(D18:D45) -> 264307.09
B49: Our bank account
B50: CITIBANK NA, NY BRANCH 111 WALL STREET / NEW YORK, 10043
B51: ABA: 21000089 / SWIFT: CITIUS33 / ACCOUNT NO:36404074
...

Sheet Financiero
B2: Lanchas de Glatil + CARP NO FORMAN PARTE DEL DESCUENTO | F2: 0.1 | H2: ROE CCL | I2: 1100
H3: ROE OFFICIAL | I3: 1058
H4: ROE AGP | I4: 1080 | J4: *Billete vendedor
B5: ITEMS | C5: MONTOS NETO | D5: MONTOS BRUTOS | E5: ROE | F5: % | G5: ER DIFFERENTIAL | H5: ISA COMMISION | I5: NET PDA
B6: TOLL DUES | C6: =Ajustada!D20-Financiero!C29 -> 106520 | E6: =I3 -> 1058 | F6: =+$E6/$I$2-1 -> -0.038181818 | G6: =+C6*F6 -> -4067.1273 | H6: =-(G6)*$F$2 -> 406.71273 | I6: =C6+G6+H6 -> 102859.59
B7: TAX ON CREDIT/DEBIT LAW 25.413 | C7: =SUM(C6)*0.012 -> 1278.24 | E7: =I3 -> 1058 | F7: =+$E7/$I$2-1 -> -0.038181818 | G7: =+C7*F7 -> -48.805527 | H7: =-(G7)*$F$2 -> 4.8805527 | I7: =C7+G7+H7 -> 1234.315
B8: PORT DUES | C8: =Ajustada!D18 -> 20090.26 | E8: =$I$3 -> 1058 | F8: =+$E8/$I$2-1 -> -0.038181818 | G8: =+C8*F8 -> -767.08265 | H8: =-(G8)*$F$2 -> 76.708265 | I8: =C8+G8+H8 -> 19399.886
B9: ENTRANCE AND LIGHT DUES | C9: =Ajustada!D19 -> 1902 | E9: =$I$3 -> 1058 | F9: =+$E9/$I$2-1 -> -0.038181818 | G9: =+C9*F9 -> -72.621818 | H9: =-(G9)*$F$2 -> 7.2621818 | I9: =C9+G9+H9 -> 1836.6404
B10: RIVER PLATE PILOTAGE | C10: =Ajustada!D21-C30 -> 32377.44 | E10: =$I$3 -> 1058 | F10: =+$E10/$I$2-1 -> -0.038181818 | G10: =+C10*F10 -> -1236.2295 | H10: =-(G10)*$F$2 -> 123.62295 | I10: =C10+G10+H10 -> 31264.833
B11: RIVER PLATE PILOTAGE (DELAY) | C11: =Ajustada!D22 -> 1512 | E11: =$I$3 -> 1058 | F11: =+$E11/$I$2-1 -> -0.038181818 | G11: =+C11*F11 -> -57.730909 | H11: =-(G11)*$F$2 -> 5.7730909 | I11: =C11+G11+H11 -> 1460.0422
B12: RIVER PLATE PILOTAGE ANCHORAGE MANEUVER | C12: =Ajustada!D23 -> 2199.12 | E12: =$I$3 -> 1058 | F12: =+$E12/$I$2-1 -> -0.038181818 | G12: =+C12*F12 -> -83.9664 | H12: =-(G12)*$F$2 -> 8.39664 | I12: =C12+G12+H12 -> 2123.5502
B13: RIVER PARANA PILOTAGE | C13: =Ajustada!D24 -> 42194.24 | E13: =$I$3 -> 1058 | F13: =+$E13/$I$2-1 -> -0.038181818 | G13: =+C13*F13 -> -1611.0528 | H13: =-(G13)*$F$2 -> 161.10528 | I13: =C13+G13+H13 -> 40744.292
B14: RIVER PARANA PILOTAGE (DELAY) | C14: =Ajustada!D25 -> 660 | E14: =$I$3 -> 1058 | F14: =+$E14/$I$2-1 -> -0.038181818 | G14: =+C14*F14 -> -25.2 | H14: =-(G14)*$F$2 -> 2.52 | I14: =C14+G14+H14 -> 637.32
B15: RIVER PARANA PILOTAGE ANCHORAGE MANEUVER | C15: =Ajustada!D26 -> 4607.68 | E15: =$I$3 -> 1058 | F15: =+$E15/$I$2-1 -> -0.038181818 | G15: =+C15*F15 -> -175.9296 | H15: =-(G15)*$F$2 -> 17.59296 | I15: =C15+G15+H15 -> 4449.3434
B16: PORT PILOTAGE | C16: =Ajustada!D27 -> 13139.854 | E16: =$I$3 -> 1058 | F16: =+$E16/$I$2-1 -> -0.038181818 | G16: =+C16*F16 -> -501.70352 | H16: =-(G16)*$F$2 -> 50.170352 | I16: =C16+G16+H16 -> 12688.321
B17: PORT PILOTAGE DELAY | C17: =Ajustada!#REF! -> #REF! | E17: =$I$3 -> 1058 | F17: =+$E17/$I$2-1 -> -0.038181818 | G17: =+C17*F17 -> #REF! | H17: =-(G17)*$F$2 -> #REF! | I17: =C17+G17+H17 -> #REF!
B18: LAUNCH SERVICES | C18: =Ajustada!D28 -> 1150 | E18: =$I$3 -> 1058 | F18: =+$E18/$I$2-1 -> -0.038181818 | G18: =+C18*F18 -> -43.909091 | H18: =-(G18)*$F$2 -> 4.3909091 | I18: =C18+G18+H18 -> 1110.4818
B19: MOORING EXPENSES | C19: =Ajustada!D29 -> 3300 | E19: =$I$3 -> 1058 | F19: =+$E19/$I$2-1 -> -0.038181818 | G19: =+C19*F19 -> -126 | H19: =-(G19)*$F$2 -> 12.6 | I19: =C19+G19+H19 -> 3186.6
B20: CUSTOM HOUSE EXPENSES | C20: =Ajustada!D30 -> 530 | E20: =$I$3 -> 1058 | F20: =+$E20/$I$2-1 -> -0.038181818 | G20: =+C20*F20 -> -20.236364 | H20: =-(G20)*$F$2 -> 2.0236364 | I20: =C20+G20+H20 -> 511.78727
B21: MIGRATION EXPENSES | C21: =Ajustada!D32 -> 1875 | E21: =$I$3 -> 1058 | F21: =+$E21/$I$2-1 -> -0.038181818 | G21: =+C21*F21 -> -71.590909 | H21: =-(G21)*$F$2 -> 7.1590909 | I21: =C21+G21+H21 -> 1810.5682
B22: SANITARY DUES | C22: =Ajustada!D33 -> 486 | E22: =$I$3 -> 1058 | F22: =+$E22/$I$2-1 -> -0.038181818 | G22: =+C22*F22 -> -18.556364 | H22: =-(G22)*$F$2 -> 1.8556364 | I22: =C22+G22+H22 -> 469.29927
B23: GARBAGE COMPULSORY INSPECTION | C23: =Ajustada!D34 -> 93 | E23: =$I$3 -> 1058 | F23: =+$E23/$I$2-1 -> -0.038181818 | G23: =+C23*F23 -> -3.5509091 | H23: =-(G23)*$F$2 -> 0.35509091 | I23: =C23+G23+H23 -> 89.804182
B24: MANDATORY HOLDS INSPECTION AT ROADS | C24: =Ajustada!D35 -> 1812 | E24: =$I$3 -> 1058 | F24: =+$E24/$I$2-1 -> -0.038181818 | G24: =+C24*F24 -> -69.185455 | H24: =-(G24)*$F$2 -> 6.9185455 | I24: =C24+G24+H24 -> 1749.7331
B25: WATCHMEN COMPULSORY SERVICES | C25: =Ajustada!#REF! -> #REF! | E25: =$I$3 -> 1058 | F25: =+$E25/$I$2-1 -> -0.038181818 | G25: =+C25*F25 -> #REF! | H25: =-(G25)*$F$2 -> #REF! | I25: =C25+G25+H25 -> #REF!
B26: HEADCLERK COMPULSORY SERVICES | C26: =Ajustada!D36 -> 2119.5 | E26: =$I$3 -> 1058 | F26: =+$E26/$I$2-1 -> -0.038181818 | G26: =+C26*F26 -> -80.926364 | H26: =-(G26)*$F$2 -> 8.0926364 | I26: =C26+G26+H26 -> 2046.6663
B27: MISCELLANEOUS | C27: =Ajustada!D43 -> 600 | E27: =$I$3 -> 1058 | F27: =+$E27/$I$2-1 -> -0.038181818 | G27: =+C27*F27 -> -22.909091 | H27: =-(G27)*$F$2 -> 2.2909091 | I27: =C27+G27+H27 -> 579.38182
B28: TAX ON CREDIT/DEBIT LAW 25.413 | C28: =SUM(C8:C27)*0.012 -> #REF! | E28: =$I$3 -> 1058 | F28: =+$E28/$I$2-1 -> -0.038181818 | G28: =+C28*F28 -> #REF! | H28: =-(G28)*$F$2 -> #REF! | I28: =C28+G28+H28 -> #REF!
B29: TOLL DUES (CARP) | C29: 9024 | E29: =I4 -> 1080 | F29: =+$E29/$I$2-1 -> -0.018181818 | G29: =+C29*F29 -> -164.07273 | H29: =-(G29)*$F$2 -> 16.407273 | I29: 0
B30: PILOT LAUNCH TRANSPORTATION RIVER PLATE | C30: 8880 | E30: =I4 -> 1080 | F30: =+$E30/$I$2-1 -> -0.018181818 | G30: =+C30*F30 -> -161.45455 | H30: =-(G30)*$F$2 -> 16.145455 | I30: 0
B31: TAX ON CREDIT/DEBIT LAW 25.413 | C31: =SUM(C29:C30)*0.012 -> 214.848 | E31: =I4 -> 1080 | F31: =+$E31/$I$2-1 -> -0.018181818 | G31: =+C31*F31 -> -3.9063273 | H31: =-(G31)*$F$2 -> 0.39063273 | I31: 0
B32: TOTAL | C32: =SUM(C6:C31) -> #REF! | G32: =SUM(G6:G31) -> #REF! | H32: =SUM(H6:H31) -> #REF! | I32: =SUM(I6:I31) -> #REF!
B33: Total sin considerar Carp + Glatil | C33: =SUM(C6:C28) -> #REF!
H34: =$I$34/$C$33 -> #REF! | I34: =C33-I32 -> #REF! | J34: NC RESULTANTE
B35: Exchange rate differential
B36: A partir de 18/6

Sheet Breakdown
F4: =Upriver!B5 -> 0
B10: Port dues | I10: Entrance and light dues
C12: =_xlfn.CONCAT("Port ",Upriver!B9," - Terminal ",Upriver!B10) -> Port - Terminal | J12: =_xlfn.CONCAT("Port ",Upriver!B9," - Terminal ",Upriver!B10) -> Port - Terminal
C13: =Upriver!B12 -> 27149 | D13: TRN*0,37* | E13: =_xlfn.CONCAT(Upriver!B18," days at port") -> 2 days at port | G13: =Upriver!A19 -> 20090.26 | J13: =Upriver!B12 -> 27149 | K13: TRN *0,058*1,2 | N13: =J13*0.058*1.2 -> 1889.5704
F16: TOTAL USD | G16: =G13 -> 20090.26 | M16: TOTAL USD | N16: =N13 -> 1889.5704
B21: Toll dues
B22: =_xlfn.CONCAT("Please advise if the same is calculated basis NRT ",C13," and summer draft ",D25) -> Please advise if the same is calculated basis NRT 27149 and summer draft 31,47
B24: TRN | D24: =Upriver!B12 -> 27149
B25: Max Draft | D25: 31.47
B26: Coefficient Results | D26: =(IF(D25<=15,15,IF(D25<=34,D25,34))-15)/D25 -> 0.52335558
B27: Coefficient Results | D27: =(IF(D25<=15,15,IF(D25<=25,D25,25))-15)/D25 -> 0.31776295
B28: Operate in Timbues Ports | D28: Yes
B31: FROM 0.0 SECTOR TO 1.1 (from Recalada to Zona Comun ) | I31: FROM 1.3 SECTOR TO 2.0 (from San Lorenzo /to Timbues) | X31: Yes
B32: BT = 4.30*NRT*2.61% | G32: =4.3*D24*2.61% -> 3046.9323 | I32: BT = 4.30*NRT*0,35% | N32: =4.3*D24*0.35% -> 408.59245 | X32: No
B33: DT = 4.30 * NRT * 44.44%* | D33: =+D26 -> 0.52335558 | G33: =4.3*D24*44.44%*D26 -> 27151.461 | I33: DT = 4.30* NRT* 5,36%* | K33: =+D27 -> 0.31776295 | N33: =4.3*D24*5.36%*D27 -> 1988.3386
B34: COEFFICIENT RESULTS FROM (Mx dft– 15)/Mx dft | F34: =+D26 -> 0.52335558 | I34: COEFFICIENT RESULTS FROM (Mx dft– 15)/Mx dft | M34: =+D27 -> 0.31776295
B35: SUBTOTAL USD | G35: =SUM(G32:G34) -> 30198.393 | I35: SUBTOTAL USD | N35: =IF(D28=X31,SUM(N32:N33),0) -> 2396.931
B37: FROM 1.1 SECTOR TO 1.2 (from Zona Comun to Parana Guazu ) CARP INVOICE | I37: FROM 2.0 SECTOR TO 1.3 (from Timbues / to RPP km 460)
B38: BT = 3,06 * NRT * 3.8% | G38: =ROUND([1]Upriver!B12*((3.8*3.06)/100),2)*1 -> 0 | I38: BT = 4.30*NRT*0,35% | N38: =4.3*D24*0.35% -> 408.59245
B39: DT = 3,06 * NRT * 17,06% * | D39: 47.49 | G39: =ROUND(D24*((17.06*3.06)/100)*F40*1,2) -> 5670.3 | I39: DT = 4.30* NRT* 5,36%* | K39: =+D27 -> 0.31776295 | N39: =4.3*D24*5.36%*D27 -> 1988.3386
B40: COEFFICIENT RESULTS FROM (Mx dft– 15)/Mx dft | F40: =(IF(D39<=15,15,IF(D39<=34,D39,34))-15)/D39 -> 0.40008423 | I40: COEFFICIENT RESULTS FROM (Mx dft– 15)/Mx dft | M40: =+D27 -> 0.31776295
B41: SUBTOTAL USD | G41: =+G39+G38 -> 5670.3 | I41: SUBTOTAL USD | N41: =IF(D28=X31,SUM(N38:N40),0) -> 2396.931
B43: FROM 1.2 SECTOR TO 1.3 (from Rio Parana Guazu to San Lorenzo ) | I43: FROM 1.3 SECTOR TO 0.0 (from San Lorenzo/ Rosario to Recalada)
B44: BT = 4.30*NRT*1,96% | G44: =4.3*D24*1.96% -> 2288.1177 | I44: BT = 4.30* NRT*8.37% | N44: =4.3*D24*8.37% -> 9771.1966
B45: DT =4.30* NRT*38.5%* | D45: =+D26 -> 0.52335558 | G45: =4.3*D24*38.5%*D26 -> 23522.305 | I45: DT = 4.30* NRT *100%* | K45: =+D26 -> 0.52335558 | N45: =4.3*D24*100%*D26 -> 61096.896
B46: COEFFICIENT RESULTS FROM (Mx dft– 15)/Mx dft | F46: =+D26 -> 0.52335558 | I46: COEFFICIENT RESULTS FROM (Mx dft– 15)/Mx dft | M46: =+D26 -> 0.52335558
B47: SUBTOTAL USD | G47: =SUM(G44:G46) -> 25810.423 | I47: SUBTOTAL USD | N47: =SUM(N44:N46) -> 70868.093
F50: TOTAL USD | H50: =G35+G41+G47+N35+N41+N47 -> 137341.07
B53: Pilotage - River Plate Pilotage
B55: Pilotage from Recalada to Zona Comun | I55: Pilotage from Zona Comun to Recalada
B57: Vessel's Fiscal Coefficient | G57: =Upriver!B11 -> 187 | I57: Vessel's Fiscal Coefficient | N57: =G57 -> 187
B58: Ship's Draft Inbound | G58: =Upriver!B29 -> 0 | I58: Ship's Draft Outbound | N58: =Upriver!C29 -> 10.41
B59: Kilometers | G59: 187 | I59: Kilometers | N59: 187
B61: ( usd 8 * Vessel's Fiscal Coefficient * 2 pilots) | G61: =G57*8*2 -> 2992 | I61: ( usd 8 * Vessel's Fiscal Coefficient * 2 pilots) | N61: =N57*8*2 -> 2992
B62: ( usd 12 * Nbr km travelled * 2 pilots ) | G62: =12*187*2 -> 4488 | I62: ( usd 12 * Nbr km travelled * 2 pilots ) | N62: =12*187*2 -> 4488
B63: % Exceeding draft | G63: =Calculos!A12*2 -> 0 | I63: % Exceeding draft | N63: =Calculos!H12*2 -> 2244
B65: Connected services ( Transportation + Pilots boats ) | G65: =IF(Upriver!G26="RIPLA",15960,IF(Upriver!G26="INDEPENDIENTE",15900,0)) -> 15960 | I65: Connected services ( Transportation + Pilots boats ) | N65: =IF(Upriver!G26="RIPLA",15960,IF(Upriver!G26="INDEPENDIENTE",15900,0)) -> 15960
B67: =_xlfn.CONCAT("Delay ( ",Upriver!B30,"hs * 2 pilots)") -> Delay ( 0hs * 2 pilots) | G67: =Upriver!E30 -> 0 | I67: =_xlfn.CONCAT("Delay ( ",Upriver!C30,"hs * 2 pilots)") -> Delay ( 6hs * 2 pilots) | N67: =Upriver!F30 -> 1800
B68: Anchorage maneuver( Vessel's Fiscal Coefficient * 14) | G68: =Upriver!E31 -> 0 | I68: Anchorage maneuver( Vessel's Fiscal Coefficient * 14) | N68: =Upriver!F31 -> 2618
B69: Due to: | I69: Due to:
...

Sheet Calculos
T1: PUERTO | U1: TERMINAL | V1: CLIENTE
O2: Elegir Proveedor | T2: XXX | U2: XXXX | V2: XX
E3: RIPLA | O3: INDEPENDIENTE | T3: CAMPANA | U3: TERMINAL 6 | V3: ATHENAI
A4: UNIDAD FISCAL | B4: =Upriver!B11 -> 187 | H4: UNIDAD FISCAL | I4: =Upriver!B11 -> 187 | O4: RIPLA | T4: RAMALLO | U4: AGD TIMBUES | V4: AL GHURAIR
A5: Pilotos | B5: =Upriver!B28 -> 2 | D5: 8.53 | E5: 9.14 | F5: 0.075 | H5: Pilotos | I5: =Upriver!C28 -> 2 | K5: 8.53 | L5: 9.14 | M5: 0.075 | T5: ROSARIO | U5: ARAUCO | V5: AXLE MARINE SINGAPURE
A6: Calado | B6: =Upriver!B29 -> 0 | D6: 9.14 | E6: 9.75 | F6: 0.15 | H6: Calado | I6: =Upriver!C29 -> 10.41 | K6: 9.14 | L6: 9.75 | M6: 0.15 | T6: SAN LORENZO | U6: BUNGE | V6: BALKAN AND BLACK SEA
A7: Demora hs | B7: =Upriver!B30 -> 0 | D7: 9.75 | E7: 10.36 | F7: 0.225 | H7: Demora hs | I7: =Upriver!C30 -> 6 | K7: 9.75 | L7: 10.36 | M7: 0.225 | T7: SAN NICOLAS | U7: CARBOCLOR | V7: BALTNAV
A8: Fondeos | B8: =Upriver!B31 -> 0 | D8: 10.36 | F8: 0.3 | H8: Fondeos | I8: =Upriver!C31 -> 1 | K8: 10.36 | M8: 0.3 | T8: SAN PEDRO | U8: CARGILL | V8: BERGE
A9: =IF(B4<=65,65*8,B4*8) -> 1496 | B9: CF*UF | H9: =IF(I4<=65,65*8,I4*8) -> 1496 | I9: CF*UF | T9: VILLA CONSTITUCION | U9: COFCO PGSM | V9: BOLTEN
A10: =+A9+A11 -> 3740 | B10: tarifa básica | H10: =+H9+H11 -> 3740 | I10: tarifa básica | T10: ZARATE | U10: COFCO TIMBUES | V10: CANAL ROJO
A11: =12*187 -> 2244 | B11: recorrido | H11: =12*187 -> 2244 | I11: recorrido | T11: NUEVA PALMIRA | U11: DELTA DOCK | V11: CENTURION BULK
A12: =IF(B6<=8.53,A10*0,IF(B6<=9.14,A10*F5,IF(B6<=9.75,A10*F6,IF(B6<=10.36,A10*F7,IF(B6>=10.37,A10*F8,IF(B6>=10.97,A10*B6,IF(B6>=10.98,A10*B4,0))))))) -> 0 | B12: ADIC CALADO | H12: =IF(I6<=8.53,H10*0,IF(I6<=9.14,H10*M5,IF(I6<=9.75,H10*M6,IF(I6<=10.36,H10*M7,IF(I6>=10.37,H10*M8,IF(I6>=10.97,H10*I6,IF(I6>=10.98,H10*I4,0))))))) -> 1122 | I12: ADIC CALADO | T12: ARROYO SECO | U12: DEMPA | V12: CARGILL
A13: 265 | B13: traslado | H13: 265 | I13: traslado | U13: GRAL. LAGOS | V13: CEFETRA SPA
A14: 1580 | B14: estadía | H14: 1580 | I14: estadía | U14: DREYFUS | V14: CJ ASIA
A15: 800 | B15: Guardia pasiva | H15: 800 | I15: Guardia pasiva | P15: Razones fondeos/demoras: | U15: MARIPASA | V15: CJ ITALY
A16: 2030 | B16: Costo operativo | H16: 2030 | I16: Costo operativo | U16: MINERA ALUMBRERA | V16: CLEARLAKE - GUNVOR
A17: 1083 | B17: lancha ZC | H17: 1083 | I17: lancha ZC | P17: Bunker operation in Zona comun | U17: PAMPA | V17: CLIPPER
A18: =+B7*150*B5 -> 0 | B18: Demora | H18: =+I7*150*I5 -> 1800 | I18: Demora | P18: Inward clearance granted by Port Authorities. | U18: PUERTO NUEVO | V18: COFCO ARGENTINA
A19: =+B4*14*B8 -> 0 | B19: fondeo | H19: =+I4*14*I8 -> 2618 | I19: fondeo | P19: Dense fog | U19: RAMALLO | V19: CORNHILL - PAN OCEAN
P20: Awaiting free beth | U20: RENOVA | V20: COSCO ARGENTINA
P21: Awaiting authorization | U21: SAN PEDRO | V21: D AMICO
P22: Load delay | U22: SAN BENITO | V22: DRYDEL SHIPPING
P23: Channel traffic | U23: SIDERAR | V23: FAIRFIELD
P24: Weather conditions | U24: SIDERCA | V24: FEDNAV
E25: PARANA | U25: TPR | V25: GENCO SHIPPING
U26: VICENTIN | V26: HAFNIA
A27: ENTRADA | D27: MOV | G27: MOV | J27: SALIDA | U27: ADM | V27: HBC HAMBURG BULK CARRIERS
A28: CF | B28: =Upriver!B11 -> 187 | D28: CF | E28: =B28 -> 187 | G28: CF | H28: =E28 -> 187 | J28: CF | K28: =B28 -> 187 | V28: HUDSON SHIPPING
A29: Pilotos | B29: =Upriver!B38 -> 2 | D29: Pilotos | E29: =Upriver!C38 -> 0 | G29: Pilotos | H29: =Upriver!D38 -> 0 | J29: Pilotos | K29: =Upriver!E38 -> 2 | V29: KOPAK SHIPPING
A30: Distancia | B30: =Upriver!B39 -> 391 | D30: Distancia | E30: =Upriver!C39 -> 0 | G30: Distancia | H30: =Upriver!D39 -> 0 | J30: Distancia | K30: =Upriver!E39 -> 377 | V30: LAURITZEN
A31: Calado extra | B31: =Upriver!B40 -> 0 | D31: Calado extra | E31: =Upriver!C40 -> 0 | G31: Calado extra | H31: =Upriver!D40 -> 0 | J31: Calado extra | K31: =Upriver!E40 -> 10.41 | V31: LOUIS DREYFUS
A32: Demora | B32: =Upriver!B41 -> 0 | D32: Demora | E32: =Upriver!C41 -> 0 | G32: Demora | H32: =Upriver!D41 -> 0 | J32: Demora | K32: =Upriver!E41 -> 2.5 | V32: M.T. MARITIME
A33: Fondeo | B33: =Upriver!B42 -> 1 | D33: Fondeo | E33: =Upriver!C42 -> 0 | G33: Fondeo | H33: =Upriver!D42 -> 0 | J33: Fondeo | K33: =Upriver!E42 -> 1 | V33: MANSEL
A34: =+B30*12*B29 -> 9384 | B34: Recorrido * Prácticos | D34: =+E30*12*E29 -> 0 | E34: Recorrido * Prácticos | G34: =+H30*12*H29 -> 0 | H34: Recorrido * Prácticos | J34: =+K30*12*K29 -> 9048 | K34: Recorrido * Prácticos | V34: MARUBENI
A35: =IF(B28<=65,65*8*B29,B28*8*B29) -> 2992 | B35: Unidad física | D35: =IF(E28<=65,65*8*E29,E28*8*E29) -> 0 | E35: Unidad física | G35: =IF(H28<=65,65*8*H29,H28*8*H29) -> 0 | H35: Unidad física | J35: =IF(K28<=65,65*8*K29,K28*8*K29) -> 2992 | K35: Unidad física | V35: MARVESA
A36: =IF(B31<=8.53,SUM(A34:A35)*0,IF(B31<=9.14,SUM(A34:A35)*C44,IF(B31<=9.75,SUM(A34:A35)*C45,IF(B31<=10.36,SUM(A34:A35)*C46,IF(B31>=10.37,SUM(A34:A35)*C47,IF(B31>=10.97,SUM(A34:A35)*C47,IF(B31>=10.98,SUM(A34:A35)*C47,0))))))) -> 0 | B36: Exceso de calado | D36: =IF(E31<=8.53,SUM(D34:D35)*0,IF(E31<=9.14,SUM(D34:D35)*F44,IF(E31<=9.75,SUM(D34:D35)*F45,IF(E31<=10.36,SUM(D34:D35)*F46,IF(E31>=10.37,SUM(D34:D35)*F47,IF(E31>=10.97,SUM(D34:D35)*F47,IF(E31>=10.98,SUM(D34:D35)*F47,0))))))) -> 0 | E36: Exceso de calado | G36: =IF(H31<=8.53,SUM(G34:G35)*0,IF(H31<=9.14,SUM(G34:G35)*I44,IF(H31<=9.75,SUM(G34:G35)*I45,IF(H31<=10.36,SUM(G34:G35)*I46,IF(H31>=10.37,SUM(G34:G35)*I47,IF(H31>=10.97,SUM(G34:G35)*I47,IF(H31>=10.98,SUM(G34:G35)*I47,0))))))) -> 0 | H36: Exceso de calado | J36: =IF(K31<=8.53,SUM(J34:J35)*0,IF(K31<=9.14,SUM(J34:J35)*L44,IF(K31<=9.75,SUM(J34:J35)*L45,IF(K31<=10.36,SUM(J34:J35)*L46,IF(K31>=10.37,SUM(J34:J35)*L47,IF(K31>=10.97,SUM(J34:J35)*L47,IF(K31>=10.98,SUM(J34:J35)*L47,0))))))) -> 3612 | K36: Exceso de calado | V36: MITSUI OSK LINES
A37: =B32*150*B29 -> 0 | B37: Demora | D37: =E32*150*E29 -> 0 | E37: Demora | G37: =H32*150*H337 -> 0 | H37: Demora | J37: =K32*150*K29 -> 750 | K37: Demora | V37: MUR SHIPPING
A38: =+B28*14*B33 -> 2618 | B38: Fondeo | D38: =+E28*14*E33 -> 0 | E38: Fondeo | G38: =+H28*14*H33 -> 0 | H38: Fondeo | J38: =+K28*14*K33 -> 2618 | K38: Fondeo | V38: NACHIPA
A39: =4980*B29 -> 9960 | B39: Conexos (Lanchas) | D39: =4980*E29 -> 0 | E39: Conexos (Lanchas) | G39: =4980*H29 -> 0 | H39: Conexos (Lanchas) | J39: =4980*K29 -> 9960 | K39: Conexos (Lanchas) | V39: NARVAL CHARTERING
A40: 0 | B40: Transporte Adicional | D40: 0 | E40: Transporte Adicional | G40: 0 | H40: Transporte Adicional | J40: 0 | K40: Transporte Adicional | V40: NAVIG8
...
